<?xml version="1.0" ?>
<!-- =================================================================================== -->
<!-- |    This document was autogenerated by xacro from vektor.xacro                   | -->
<!-- |    EDITING THIS FILE BY HAND IS NOT RECOMMENDED                                 | -->
<!-- =================================================================================== -->
<robot name="vektor">
  <!-- Specify some standard inertial calculations
  https://en.wikipedia.org/wiki/List_of_moments_of_inertia -->
  <!-- These make use of xacro's mathematical functionality -->
  <!-- Solid -->
  <material name="white">
    <color rgba="1.0 1.0 1.0 1.0"/>
  </material>
  <material name="Gray">
    <color rgba="0.6 0.6 0.6 1.0"/>
  </material>
  <material name="black">
    <color rgba="0.0 0.0 0.0 1.0"/>
  </material>
  <material name="red">
    <color rgba="1.0 0.0 0.0 1.0"/>
  </material>
  <material name="yellow">
    <color rgba="1.0 1.0 0.0 1.0"/>
  </material>
  <material name="green">
    <color rgba="0.0 1.0 0.0 1.0"/>
  </material>
  <material name="blue">
    <color rgba="0.0 0.0 1.0 1.0"/>
  </material>
  <!-- Exotic -->
  <material name="paper">
    <color rgba="0.85 0.80 0.73 1.0"/>
  </material>
  <material name="Salmon">
    <color rgba="0.9 0.5 0.5 1.0"/>
  </material>
  <material name="Dark purple">
    <color rgba="0.3 0.1 0.4 1.0"/>
  </material>
  <material name="Olive">
    <color rgba="0.5 0.6 0.3 1.0"/>
  </material>
  <link name="base_footprint"/>
  <link name="base_link"/>
  <joint name="base_joint" type="fixed">
    <parent link="base_footprint"/>
    <child link="base_link"/>
    <origin xyz="0 0 0.05"/>
  </joint>
  <link name="chassis_link">
    <visual>
      <origin xyz="0.15 0 0.075"/>
      <geometry>
        <box size="0.3 0.3 0.15"/>
      </geometry>
      <material name="paper"/>
    </visual>
    <collision>
      <origin xyz="0.15 0 0.075"/>
      <geometry>
        <box size="0.3 0.3 0.15"/>
      </geometry>
    </collision>
    <inertial>
      <origin rpy="0 0 0" xyz="0.15 0 0.075"/>
      <mass value="0.5"/>
      <inertia ixx="0.004687499999999999" ixy="0.0" ixz="0.0" iyy="0.004687499999999999" iyz="0.0" izz="0.0075"/>
    </inertial>
  </link>
  <joint name="chassis_joint" type="fixed">
    <parent link="base_link"/>
    <child link="chassis_link"/>
    <origin xyz="-0.1 0 0"/>
  </joint>
  <link name="left_wheel_link">
    <visual>
      <geometry>
        <cylinder length="0.04" radius="0.05"/>
      </geometry>
      <material name="blue"/>
    </visual>
    <collision>
      <geometry>
        <cylinder length="0.04" radius="0.05"/>
      </geometry>
    </collision>
    <inertial>
      <origin rpy="0 0 0" xyz="0 0 0"/>
      <mass value="0.1"/>
      <inertia ixx="7.583333333333335e-05" ixy="0.0" ixz="0.0" iyy="7.583333333333335e-05" iyz="0.0" izz="0.00012500000000000003"/>
    </inertial>
  </link>
  <joint name="left_wheel_joint" type="continuous">
    <parent link="base_link"/>
    <child link="left_wheel_link"/>
    <origin rpy="-1.5707963267948966 0 0" xyz="0 0.17 0"/>
    <axis xyz="0 0 1"/>
  </joint>
  <link name="right_wheel_link">
    <visual>
      <geometry>
        <cylinder length="0.04" radius="0.05"/>
      </geometry>
      <material name="blue"/>
    </visual>
    <collision>
      <geometry>
        <cylinder length="0.04" radius="0.05"/>
      </geometry>
    </collision>
    <inertial>
      <origin rpy="0 0 0" xyz="0 0 0"/>
      <mass value="0.1"/>
      <inertia ixx="7.583333333333335e-05" ixy="0.0" ixz="0.0" iyy="7.583333333333335e-05" iyz="0.0" izz="0.00012500000000000003"/>
    </inertial>
  </link>
  <joint name="right_wheel_joint" type="continuous">
    <parent link="base_link"/>
    <child link="right_wheel_link"/>
    <origin rpy="1.5707963267948966 0 0" xyz="0 -0.17 0"/>
    <axis xyz="0 0 -1"/>
  </joint>
  <link name="caster_wheel_link">
    <visual>
      <geometry>
        <sphere radius="0.05"/>
      </geometry>
      <material name="yellow"/>
    </visual>
    <collision>
      <geometry>
        <sphere radius="0.05"/>
      </geometry>
    </collision>
    <inertial>
      <origin rpy="0 0 0" xyz="0 0 0"/>
      <mass value="0.1"/>
      <inertia ixx="0.00010000000000000005" ixy="0.0" ixz="0.0" iyy="0.00010000000000000005" iyz="0.0" izz="0.00010000000000000005"/>
    </inertial>
  </link>
  <joint name="caster_wheel_joint" type="fixed">
    <parent link="base_link"/>
    <child link="caster_wheel_link"/>
    <origin xyz="0.14 0 0"/>
  </joint>
  <gazebo reference="caster_wheel_link">
    <mu1 value="0.001"/>
    <mu2 value="0.001"/>
  </gazebo>
  <gazebo>
    <plugin filename="libignition-gazebo-joint-state-publisher-system" name="ignition::gazebo::systems::JointStatePublisher">
      <!-- JointStatePublisher Class Reference -->
      <!--
      https://gazebosim.org/api/gazebo/3.3/classignition_1_1gazebo_1_1systems_1_1JointStatePublisher.html -->
      <topic>joint_states</topic>
      <!-- Custom topic on which this system will publish joint state messages. -->
      <!-- [TODO] SET PUBLISH FREQUENCY / UPDATE RATE. UNKNOWN TAG. -->
      <!-- <joint_name>left_wheel_joint</joint_name> -->
      <!-- <joint_name>right_wheel_joint</joint_name> -->
      <!-- Name of a joint to publish. This parameter can be specified multiple times, and is
      optional. -->
      <!-- All joints in a model will be published if joint names are not specified. -->
    </plugin>
  </gazebo>
  <gazebo>
    <plugin filename="libignition-gazebo-sensors-system" name="ignition::gazebo::systems::Sensors">
      <!-- Sensors Class (LiDAR, camera, depth camera etc). -->
      <render_engine>ogre2</render_engine>
    </plugin>
  </gazebo>
  <link name="main_link">
    <visual>
      <geometry>
        <cylinder length="0.04" radius="0.05"/>
      </geometry>
      <material name="Olive"/>
    </visual>
    <collision>
      <geometry>
        <cylinder length="0.04" radius="0.05"/>
      </geometry>
    </collision>
    <inertial>
      <origin rpy="0 0 0" xyz="0 0 0"/>
      <mass value="0.1"/>
      <inertia ixx="7.583333333333335e-05" ixy="0.0" ixz="0.0" iyy="7.583333333333335e-05" iyz="0.0" izz="0.00012500000000000003"/>
    </inertial>
  </link>
  <joint name="lidar_joint" type="fixed">
    <parent link="chassis_link"/>
    <child link="main_link"/>
    <origin rpy="0 0 0" xyz="0.1 0 0.175"/>
  </joint>
  <gazebo reference="main_link">
    <sensor name="main_lidar" type="gpu_lidar">
      <pose>0 0 0 0 0 0</pose>
      <topic>scan</topic>
      <ignition_frame_id>main_link</ignition_frame_id>
      <update_rate>10</update_rate>
      <lidar>
        <scan>
          <horizontal>
            <samples>640</samples>
            <resolution>1</resolution>
            <min_angle>-3.14</min_angle>
            <max_angle>3.14</max_angle>
          </horizontal>
          <vertical>
            <samples>1</samples>
            <resolution>1</resolution>
            <min_angle>0.0</min_angle>
            <max_angle>0.0</max_angle>
          </vertical>
        </scan>
        <range>
          <min>0.08</min>
          <max>10.0</max>
          <resolution>0.01</resolution>
        </range>
      </lidar>
      <always_on>true</always_on>
      <visualize>true</visualize>
    </sensor>
  </gazebo>
  <link name="main_rgbd_camera_link">
    <visual>
      <geometry>
        <box size="0.01 0.03 0.03"/>
      </geometry>
      <material name="green"/>
    </visual>
    <collision>
      <geometry>
        <box size="0.01 0.03 0.03"/>
      </geometry>
    </collision>
    <inertial>
      <origin rpy="0 0 0" xyz="0 0 0"/>
      <mass value="0.5"/>
      <inertia ixx="7.5e-05" ixy="0.0" ixz="0.0" iyy="4.1666666666666665e-05" iyz="0.0" izz="4.1666666666666665e-05"/>
    </inertial>
  </link>
  <joint name="main_rgbd_camera_joint" type="fixed">
    <parent link="base_link"/>
    <child link="main_rgbd_camera_link"/>
    <origin rpy="0 0 0" xyz="0.205 0 0.075"/>
  </joint>
  <gazebo reference="main_rgbd_camera_link">
    <sensor name="main_rgbd_camera" type="rgbd_camera">
      <update_rate>30</update_rate>
      <topic>rgbd</topic>
      <ignition_frame_id>main_rgbd_camera_link</ignition_frame_id>
      <camera>
        <horizontal_fov>1.05</horizontal_fov>
        <image>
          <width>640</width>
          <height>480</height>
          <format>R8G8B8</format>
        </image>
        <clip>
          <near>0.1</near>
          <far>20.0</far>
        </clip>
      </camera>
    </sensor>
  </gazebo>
  <gazebo>
    <plugin filename="libignition-gazebo-diff-drive-system" name="ignition::gazebo::systems::DiffDrive">
      <!-- DiffDrive Class Reference -->
      <!-- https://gazebosim.org/api/gazebo/5.1/classignition_1_1gazebo_1_1systems_1_1DiffDrive.html -->
      <left_joint>left_wheel_joint</left_joint>
      <!-- Name of a joint that controls a left wheel. -->
      <!-- This element can appear multiple times, and must appear at least once. -->
      <right_joint>right_wheel_joint</right_joint>
      <!-- Name of a joint that controls a right wheel. -->
      <!-- This element can appear multiple times, and must appear at least once. -->
      <wheel_separation>0.35</wheel_separation>
      <!-- Distance between wheels, in meters. The default value is 1.0m.-->
      <!-- This element is optional, although it is recommended to be included with an appropriate
      value. -->
      <wheel_radius>0.05</wheel_radius>
      <!-- Wheel radius in meters. The default value is 0.2m. -->
      <!-- This element is optional, although it is recommended to be included with an appropriate
      value. -->
      <odom_publish_frequency>100</odom_publish_frequency>
      <!-- Odometry publication frequency. -->
      <!-- This element is optional, and the default value is 50Hz. -->
      <topic>cmd_vel</topic>
      <!-- Custom topic that this system will subscribe to in order to receive command velocity
      messages.  -->
      <!-- This element if optional, and the default value is /model/{name_of_model}/cmd_vel. -->
      <odom_topic>odom</odom_topic>
      <!-- Custom topic on which this system will publish odometry messages. -->
      <!-- This element if optional, and the default value is /model/{name_of_model}/odometry. -->
      <tf_topic>tf</tf_topic>
      <!-- Custom topic on which this system will publish the transform from frame_id to
      child_frame_id. -->
      <!-- This element if optional, and the default value is /model/{name_of_model}/tf. -->
      <frame_id>odom</frame_id>
      <!-- Custom frame_id field that this system will use as the origin of the odometry transform
      in 
      both the <tf_topic> ignition.msgs.Pose_V message and the <odom_topic> ignition.msgs.Odometry
      message. -->
      <!-- This element if optional, and the default value is {name_of_model}/odom. -->
      <child_frame_id>base_footprint</child_frame_id>
      <!-- Custom child_frame_id that this system will use as the target of the odometry transform
      in
      both the <tf_topic> ignition.msgs.Pose_V message and the <odom_topic> ignition.msgs.Odometry
      message. -->
      <!-- This element if optional, and the default value is {name_of_model}/{name_of_link}. -->
    </plugin>
  </gazebo>
</robot>
