<?xml version="1.1" encoding="UTF-8"?>
<robot xmlns:xacro="http://www.ros.org/wiki/xacro">

  <xacro:macro name="wheel" params="prefix radius length parent *origin *axis">
    <link name="${prefix}_wheel_link">
      <visual>
        <geometry>
          <cylinder radius="${radius}" length="${length}" />
        </geometry>
        <material name="blue" />
      </visual>
      <collision>
        <geometry>
          <cylinder radius="${radius}" length="${length}" />
        </geometry>
      </collision>
      <xacro:inertial_cylinder mass="0.1" radius="${radius}" length="${length}">
        <origin xyz="0 0 0" rpy="0 0 0" />
      </xacro:inertial_cylinder>
    </link>

    <joint name="${prefix}_wheel_joint" type="continuous">
      <parent link="${parent}" />
      <child link="${prefix}_wheel_link" />
      <xacro:insert_block name="origin" />
      <xacro:insert_block name="axis" />
    </joint>

  </xacro:macro>

</robot>